<?xml version="1.0"?>
<robot xmlns:xacro="http://www.ros.org/wiki/xacro">

    <xacro:include filename="inertial_macros.xacro" />

    <material name="white">
        <color rgba="1 1 1 1" />
    </material>

    <material name="orange">
        <color rgba="1 0.3 0.1 1" />
    </material>

    <material name="blue">
        <color rgba="0.2 0.2 1 1" />
    </material>

    <material name="black">
        <color rgba="0 0 0 1" />
    </material>


    <!-- BASE LINK -->

    <link name="base_link">

    </link>

    <!-- CHASSIS LINK -->

    <joint name="chassis_joint" type="fixed">
        <parent link="base_link"/>
        <child link="chassis"/>
        <origin xyz="-0.03 0 0"/>
    </joint>

    <link name="chassis">
        <visual>
            <origin xyz="0.125 0 0.03"/>
            <geometry>
                <box size="0.255 0.205 0.08"/>
            </geometry>
            <material name="white"/>
        </visual>
        <collision>
            <origin xyz="0.125 0 0.03"/>
            <geometry>
                <box size="0.255 0.205 0.08"/>
            </geometry>
        </collision>
        <xacro:inertial_box mass="2.0" x="0.255" y="0.205" z="0.08">
            <origin xyz="0.125 0 0.03" rpy="0 0 0"/>
        </xacro:inertial_box>
    </link>

    <gazebo reference="chassis">
        <material>Gazebo/White</material>
    </gazebo>

    <!-- LEFT WHEEL LINK -->

    <joint name="left_wheel_joint" type="continuous">
        <parent link="base_link"/>
        <child link="left_wheel" />
        <origin xyz="0 0.1255 0" rpy="-${pi/2} 0 0"/>
        <axis xyz="0 0 1"/>
    </joint>

    <link name="left_wheel">
        <visual>
            <geometry>
                <cylinder radius="0.06" length="0.05"/>
            </geometry>
            <material name="blue" />
        </visual>
        <collision>
            <geometry>
                <cylinder radius="0.06" length="0.05"/>
            </geometry>
        </collision>
        <xacro:inertial_cylinder mass="0.15" length="0.05" radius="0.06">
            <origin xyz="0 0 0" rpy="0 0 0"/>
        </xacro:inertial_cylinder>
    </link>

    <gazebo reference="left_wheel">
        <material>Gazebo/Blue</material>
    </gazebo>

    <!-- RIGHT WHEEL LINK -->

    <joint name="right_wheel_joint" type="continuous">
        <parent link="base_link"/>
        <child link="right_wheel" />
        <origin xyz="0 -0.1255 0" rpy="${pi/2} 0 0"/>
        <axis xyz="0 0 -1"/>
    </joint>

    <link name="right_wheel">
        <visual>
            <geometry>
                <cylinder radius="0.06" length="0.05"/>
            </geometry>
            <material name="blue" />
        </visual>
        <collision>
            <geometry>
                <cylinder radius="0.06" length="0.05"/>
            </geometry>
        </collision>
        <xacro:inertial_cylinder mass="0.15" length="0.05" radius="0.06">
            <origin xyz="0 0 0" rpy="0 0 0"/>
        </xacro:inertial_cylinder>
    </link>

    <gazebo reference="right_wheel">
        <material>Gazebo/Blue</material>
    </gazebo>

    <!-- FRONT LEFT WHEEL LINK -->

    <joint name="front_left_wheel_joint" type="fixed">
        <parent link="base_link"/>
        <child link="front_left_wheel" />
        <origin xyz="0.2 0.1255 0" rpy="-${pi/2} 0 0"/>
        <axis xyz="0 0 1"/>
    </joint>

    <link name="front_left_wheel">
        <visual>
            <geometry>
                <cylinder radius="0.06" length="0.05"/>
            </geometry>
            <material name="black" />
        </visual>
        <collision>
            <geometry>
                <cylinder radius="0.06" length="0.05"/>
            </geometry>
        </collision>
        <xacro:inertial_cylinder mass="0.15" length="0.05" radius="0.06">
            <origin xyz="0 0 0" rpy="0 0 0"/>
        </xacro:inertial_cylinder>
    </link>

    <gazebo reference="front_left_wheel">
        <material>Gazebo/Black</material>
        <mu1 value="0.001"/>
        <mu2 value="0.001"/>
    </gazebo>

    <!-- FRONT RIGHT WHEEL LINK -->

    <joint name="front_right_wheel_joint" type="fixed">
        <parent link="base_link"/>
        <child link="front_right_wheel" />
        <origin xyz="0.2 -0.1255 0" rpy="${pi/2} 0 0"/>
        <axis xyz="0 0 -1"/>
    </joint>

    <link name="front_right_wheel">
        <visual>
            <geometry>
                <cylinder radius="0.06" length="0.05"/>
            </geometry>
            <material name="black" />
        </visual>
        <collision>
            <geometry>
                <cylinder radius="0.06" length="0.05"/>
            </geometry>
        </collision>
        <xacro:inertial_cylinder mass="0.15" length="0.05" radius="0.06">
            <origin xyz="0 0 0" rpy="0 0 0"/>
        </xacro:inertial_cylinder>
    </link>

    <gazebo reference="front_right_wheel">
        <material>Gazebo/Black</material>
        <mu1 value="0.001"/>
        <mu2 value="0.001"/>
    </gazebo>
    

</robot>